<?xml version="1.0" ?>
<!-- =================================================================================== -->
<!-- |    This document was autogenerated by xacro from human_tworobot.urdf.xacro      | -->
<!-- |    EDITING THIS FILE BY HAND IS NOT RECOMMENDED                                 | -->
<!-- =================================================================================== -->
<robot name="human_tworobot">
  <!-- BASE LINK -->
  <link name="world"/>
  <!-- <link name="${connected_to}"/> -->
  <joint name="leftpanda_joint_world" type="fixed">
    <parent link="world"/>
    <child link="leftpanda_link0"/>
    <origin rpy="0.000 0.000 0.000" xyz="0.000 0.500 0.000"/>
  </joint>
  <link name="leftpanda_link0">
    <visual>
      <!-- <origin xyz="${xyz}" rpy="${rpy}"/> -->
      <geometry>
        <mesh filename="package://master_optimization/model/meshes/visual/link0.dae"/>
      </geometry>
      <material name="">
        <color rgba="1 1 1 1"/>
      </material>
    </visual>
    <collision>
      <!-- <origin xyz="${xyz}" rpy="${rpy}"/> -->
      <geometry>
        <mesh filename="package://master_optimization/model/meshes/collision/link0.stl"/>
      </geometry>
    </collision>
  </link>
  <link name="leftpanda_link1">
    <inertial>
      <mass value="4.970684"/>
      <origin rpy="0 0 0" xyz="3.875e-03 2.081e-03 -0.1750"/>
      <inertia ixx="7.0337e-01" ixy="-1.3900e-04" ixz="6.7720e-03" iyy="7.0661e-01" iyz="1.9169e-02" izz="9.1170e-03"/>
    </inertial>
    <visual>
      <!-- <origin xyz="${xyz}" rpy="${rpy}"/> -->
      <geometry>
        <mesh filename="package://master_optimization/model/meshes/visual/link1.dae"/>
      </geometry>
      <material name="">
        <color rgba="1 1 1 1"/>
      </material>
    </visual>
    <collision>
      <!-- <origin xyz="${xyz}" rpy="${rpy}"/> -->
      <geometry>
        <mesh filename="package://master_optimization/model/meshes/collision/link1.stl"/>
      </geometry>
    </collision>
  </link>
  <joint name="leftpanda_joint1" type="revolute">
    <safety_controller k_position="100.0" k_velocity="40.0" soft_lower_limit="-2.8973" soft_upper_limit="2.8973"/>
    <origin rpy="0 0 0" xyz="0 0 0.333"/>
    <parent link="leftpanda_link0"/>
    <child link="leftpanda_link1"/>
    <axis xyz="0 0 1"/>
    <limit effort="2000" lower="-2.8973" upper="2.8973" velocity="2.1750"/>
  </joint>
  <link name="leftpanda_link2">
    <inertial>
      <mass value="0.646926"/>
      <origin rpy="0 0 0" xyz="-3.141e-03 -2.872e-02 3.495e-03"/>
      <inertia ixx="7.9620e-03" ixy="-3.9250e-03" ixz="1.0254e-02" iyy="2.8110e-02" iyz="7.0400e-04" izz="2.5995e-02"/>
    </inertial>
    <visual>
      <!-- <origin xyz="${xyz}" rpy="${rpy}"/> -->
      <geometry>
        <mesh filename="package://master_optimization/model/meshes/visual/link2.dae"/>
      </geometry>
      <material name="">
        <color rgba="1 1 1 1"/>
      </material>
    </visual>
    <collision>
      <!-- <origin xyz="${xyz}" rpy="${rpy}"/> -->
      <geometry>
        <mesh filename="package://master_optimization/model/meshes/collision/link2.stl"/>
      </geometry>
    </collision>
  </link>
  <joint name="leftpanda_joint2" type="revolute">
    <safety_controller k_position="100.0" k_velocity="40.0" soft_lower_limit="-1.7628" soft_upper_limit="1.7628"/>
    <origin rpy="-1.5707963267948966 0 0" xyz="0 0 0"/>
    <parent link="leftpanda_link1"/>
    <child link="leftpanda_link2"/>
    <axis xyz="0 0 1"/>
    <limit effort="2000" lower="-1.7628" upper="1.7628" velocity="2.1750"/>
  </joint>
  <link name="leftpanda_link3">
    <inertial>
      <mass value="3.228604"/>
      <origin rpy="0 0 0" xyz="2.7518e-02 3.9252e-02 -6.6502e-02"/>
      <inertia ixx="3.7242e-02" ixy="-4.7610e-03" ixz="-1.1396e-02" iyy="3.6155e-02" iyz="-1.2805e-02" izz="1.0830e-02"/>
    </inertial>
    <visual>
      <!-- <origin xyz="${xyz}" rpy="${rpy}"/> -->
      <geometry>
        <mesh filename="package://master_optimization/model/meshes/visual/link3.dae"/>
      </geometry>
      <material name="">
        <color rgba="1 1 1 1"/>
      </material>
    </visual>
    <collision>
      <!-- <origin xyz="${xyz}" rpy="${rpy}"/> -->
      <geometry>
        <mesh filename="package://master_optimization/model/meshes/collision/link3.stl"/>
      </geometry>
    </collision>
  </link>
  <joint name="leftpanda_joint3" type="revolute">
    <safety_controller k_position="100.0" k_velocity="40.0" soft_lower_limit="-2.8973" soft_upper_limit="2.8973"/>
    <origin rpy="1.5707963267948966 0 0" xyz="0 -0.316 0"/>
    <parent link="leftpanda_link2"/>
    <child link="leftpanda_link3"/>
    <axis xyz="0 0 1"/>
    <limit effort="2000" lower="-2.8973" upper="2.8973" velocity="2.1750"/>
  </joint>
  <link name="leftpanda_link4">
    <inertial>
      <mass value="3.587895"/>
      <origin rpy="0 0 0" xyz="-5.317e-02 1.04419e-01 2.7454e-02"/>
      <inertia ixx="2.5853e-02" ixy="7.7960e-03" ixz="-1.3320e-03" iyy="1.9552e-02" iyz="8.6410e-03" izz="2.8323e-02"/>
    </inertial>
    <visual>
      <!-- <origin xyz="${xyz}" rpy="${rpy}"/> -->
      <geometry>
        <mesh filename="package://master_optimization/model/meshes/visual/link4.dae"/>
      </geometry>
      <material name="">
        <color rgba="1 1 1 1"/>
      </material>
    </visual>
    <collision>
      <!-- <origin xyz="${xyz}" rpy="${rpy}"/> -->
      <geometry>
        <mesh filename="package://master_optimization/model/meshes/collision/link4.stl"/>
      </geometry>
    </collision>
  </link>
  <joint name="leftpanda_joint4" type="revolute">
    <safety_controller k_position="100.0" k_velocity="40.0" soft_lower_limit="-3.0718" soft_upper_limit="0.0698"/>
    <!-- soft_upper_limitr should be -0.0698, but that brakes simulation when initial position for this joint is 0.0 -->
    <origin rpy="1.5707963267948966 0 0" xyz="0.0825 0 0"/>
    <parent link="leftpanda_link3"/>
    <child link="leftpanda_link4"/>
    <axis xyz="0 0 1"/>
    <limit effort="2000" lower="-3.0718" upper="0.0698" velocity="2.1750"/>
    <!-- upper should be -0.0698, but that brakes simulation when initial position for this joint is 0.0 -->
  </joint>
  <link name="leftpanda_link5">
    <inertial>
      <mass value="1.225946"/>
      <origin rpy="0 0 0" xyz="-1.1953e-02 4.1065e-02 -3.8437e-02"/>
      <inertia ixx="3.5549e-02" ixy="-2.1170e-03" ixz="-4.0370e-03" iyy="2.9474e-02" iyz="2.2900e-04" izz="8.6270e-03"/>
    </inertial>
    <visual>
      <!-- <origin xyz="${xyz}" rpy="${rpy}"/> -->
      <geometry>
        <mesh filename="package://master_optimization/model/meshes/visual/link5.dae"/>
      </geometry>
      <material name="">
        <color rgba="1 1 1 1"/>
      </material>
    </visual>
    <collision>
      <!-- <origin xyz="${xyz}" rpy="${rpy}"/> -->
      <geometry>
        <mesh filename="package://master_optimization/model/meshes/collision/link5.stl"/>
      </geometry>
    </collision>
  </link>
  <joint name="leftpanda_joint5" type="revolute">
    <safety_controller k_position="100.0" k_velocity="40.0" soft_lower_limit="-2.8973" soft_upper_limit="2.8973"/>
    <origin rpy="-1.5707963267948966 0 0" xyz="-0.0825 0.384 0"/>
    <parent link="leftpanda_link4"/>
    <child link="leftpanda_link5"/>
    <axis xyz="0 0 1"/>
    <limit effort="2000" lower="-2.8973" upper="2.8973" velocity="2.6100"/>
  </joint>
  <link name="leftpanda_link6">
    <inertial>
      <mass value="1.666555"/>
      <origin rpy="0 0 0" xyz="6.0149e-02 -1.4117e-02 -1.0517e-02"/>
      <inertia ixx="1.9640e-03" ixy="1.0900e-04" ixz="-1.1580e-03" iyy="4.3540e-03" iyz="3.4100e-04" izz="5.4330e-03"/>
    </inertial>
    <visual>
      <!-- <origin xyz="${xyz}" rpy="${rpy}"/> -->
      <geometry>
        <mesh filename="package://master_optimization/model/meshes/visual/link6.dae"/>
      </geometry>
      <material name="">
        <color rgba="1 1 1 1"/>
      </material>
    </visual>
    <collision>
      <!-- <origin xyz="${xyz}" rpy="${rpy}"/> -->
      <geometry>
        <mesh filename="package://master_optimization/model/meshes/collision/link6.stl"/>
      </geometry>
    </collision>
  </link>
  <joint name="leftpanda_joint6" type="revolute">
    <safety_controller k_position="100.0" k_velocity="40.0" soft_lower_limit="-0.0175" soft_upper_limit="3.7525"/>
    <origin rpy="1.5707963267948966 0 0" xyz="0 0 0"/>
    <parent link="leftpanda_link5"/>
    <child link="leftpanda_link6"/>
    <axis xyz="0 0 1"/>
    <limit effort="12" lower="-0.0175" upper="3.7525" velocity="2.6100"/>
  </joint>
  <link name="leftpanda_link7">
    <inertial>
      <mass value="7.35522e-01"/>
      <origin rpy="0 0 0" xyz="1.0517e-02 -4.252e-03 6.1597e-02"/>
      <inertia ixx="1.2516e-02" ixy="-4.2800e-04" ixz="-1.1960e-03" iyy="1.0027e-02" iyz="-7.4100e-04" izz="4.8150e-03"/>
    </inertial>
    <visual>
      <!-- <origin xyz="${xyz}" rpy="${rpy}"/> -->
      <geometry>
        <mesh filename="package://master_optimization/model/meshes/visual/link7.dae"/>
      </geometry>
      <material name="">
        <color rgba="1 1 1 1"/>
      </material>
    </visual>
    <collision>
      <!-- <origin xyz="${xyz}" rpy="${rpy}"/> -->
      <geometry>
        <mesh filename="package://master_optimization/model/meshes/collision/link7.stl"/>
      </geometry>
    </collision>
  </link>
  <joint name="leftpanda_joint7" type="revolute">
    <safety_controller k_position="100.0" k_velocity="40.0" soft_lower_limit="-2.8973" soft_upper_limit="2.8973"/>
    <!-- <safety_controller k_position="100.0" k_velocity="40.0"/> -->
    <origin rpy="1.5707963267948966 0 0" xyz="0.088 0 0"/>
    <parent link="leftpanda_link6"/>
    <child link="leftpanda_link7"/>
    <axis xyz="0 0 1"/>
    <limit effort="12" lower="-2.8973" upper="2.8973" velocity="2.6100"/>
    <!-- <limit effort="12" velocity="2.6100"/> -->
  </joint>
  <link name="leftpanda_link8"/>
  <joint name="leftpanda_joint8" type="fixed">
    <origin rpy="0 0 0" xyz="0 0 0.107"/>
    <parent link="leftpanda_link7"/>
    <child link="leftpanda_link8"/>
    <axis xyz="0 0 0"/>
  </joint>
  <link name="leftpanda_tmp"/>
  <joint name="leftpanda_joint9" type="fixed">
    <origin rpy="0 0 1.5707" xyz="0 0 0"/>
    <parent link="leftpanda_link8"/>
    <child link="leftpanda_tmp"/>
  </joint>
  <link name="leftpanda_TCP"/>
  <joint name="leftpanda_joint10" type="fixed">
    <origin rpy="0 0.000 0" xyz="0 0 0.07"/>
    <parent link="leftpanda_tmp"/>
    <child link="leftpanda_TCP"/>
  </joint>
  <!-- <link name="${connected_to}"/> -->
  <joint name="rightpanda_joint_world" type="fixed">
    <parent link="world"/>
    <child link="rightpanda_link0"/>
    <origin rpy="-0.000 0.000 -0.000" xyz="0.000 -0.500 0.000"/>
  </joint>
  <link name="rightpanda_link0">
    <inertial>
      <mass value="2.92"/>
      <origin rpy="0 0 0" xyz="-0.025566 -2.88e-05 0.057332"/>
      <inertia ixx="0.00782229414331" ixy="-1.56191622996e-05" ixz="-0.00126005738123" iyy="0.0109027971813" iyz="1.08233858202e-05" izz="0.0102355503949"/>
    </inertial>
    <visual>
      <!-- <origin xyz="${xyz}" rpy="${rpy}"/> -->
      <geometry>
        <mesh filename="package://master_optimization/model/meshes/visual/link0.dae"/>
      </geometry>
      <material name="">
        <color rgba="1 1 1 1"/>
      </material>
    </visual>
    <collision>
      <!-- <origin xyz="${xyz}" rpy="${rpy}"/> -->
      <geometry>
        <mesh filename="package://master_optimization/model/meshes/collision/link0.stl"/>
      </geometry>
    </collision>
  </link>
  <link name="rightpanda_link1">
    <inertial>
      <mass value="2.74"/>
      <origin rpy="0 0 0" xyz="0 -0.0324958 -0.0675818"/>
      <inertia ixx="0.0180416958283" ixy="0.0" ixz="0.0" iyy="0.0159136071891" iyz="0.0046758424612" izz="0.00620690827127"/>
    </inertial>
    <visual>
      <!-- <origin xyz="${xyz}" rpy="${rpy}"/> -->
      <geometry>
        <mesh filename="package://master_optimization/model/meshes/visual/link1.dae"/>
      </geometry>
      <material name="">
        <color rgba="1 1 1 1"/>
      </material>
    </visual>
    <collision>
      <!-- <origin xyz="${xyz}" rpy="${rpy}"/> -->
      <geometry>
        <mesh filename="package://master_optimization/model/meshes/collision/link1.stl"/>
      </geometry>
    </collision>
  </link>
  <joint name="rightpanda_joint1" type="revolute">
    <safety_controller k_position="100.0" k_velocity="40.0" soft_lower_limit="-2.8973" soft_upper_limit="2.8973"/>
    <origin rpy="0 0 0" xyz="0 0 0.333"/>
    <parent link="rightpanda_link0"/>
    <child link="rightpanda_link1"/>
    <axis xyz="0 0 1"/>
    <limit effort="2000" lower="-2.8973" upper="2.8973" velocity="2.1750"/>
  </joint>
  <link name="rightpanda_link2">
    <inertial>
      <mass value="2.74"/>
      <origin rpy="0 0 0" xyz="0 -0.06861 0.0322285"/>
      <inertia ixx="0.0182856182281" ixy="0.0" ixz="0.0" iyy="0.00621358421175" iyz="-0.00472844221905" izz="0.0161514346309"/>
    </inertial>
    <visual>
      <!-- <origin xyz="${xyz}" rpy="${rpy}"/> -->
      <geometry>
        <mesh filename="package://master_optimization/model/meshes/visual/link2.dae"/>
      </geometry>
      <material name="">
        <color rgba="1 1 1 1"/>
      </material>
    </visual>
    <collision>
      <!-- <origin xyz="${xyz}" rpy="${rpy}"/> -->
      <geometry>
        <mesh filename="package://master_optimization/model/meshes/collision/link2.stl"/>
      </geometry>
    </collision>
  </link>
  <joint name="rightpanda_joint2" type="revolute">
    <safety_controller k_position="100.0" k_velocity="40.0" soft_lower_limit="-1.7628" soft_upper_limit="1.7628"/>
    <origin rpy="-1.5707963267948966 0 0" xyz="0 0 0"/>
    <parent link="rightpanda_link1"/>
    <child link="rightpanda_link2"/>
    <axis xyz="0 0 1"/>
    <limit effort="2000" lower="-1.7628" upper="1.7628" velocity="2.1750"/>
  </joint>
  <link name="rightpanda_link3">
    <inertial>
      <mass value="2.38"/>
      <origin rpy="0 0 0" xyz="0.0469893 0.0316374 -0.031704"/>
      <inertia ixx="0.00771376630908" ixy="-0.00248490625138" ixz="-0.00332147581033" iyy="0.00989108008727" iyz="-0.00217796151484" izz="0.00811723558464"/>
    </inertial>
    <visual>
      <!-- <origin xyz="${xyz}" rpy="${rpy}"/> -->
      <geometry>
        <mesh filename="package://master_optimization/model/meshes/visual/link3.dae"/>
      </geometry>
      <material name="">
        <color rgba="1 1 1 1"/>
      </material>
    </visual>
    <collision>
      <!-- <origin xyz="${xyz}" rpy="${rpy}"/> -->
      <geometry>
        <mesh filename="package://master_optimization/model/meshes/collision/link3.stl"/>
      </geometry>
    </collision>
  </link>
  <joint name="rightpanda_joint3" type="revolute">
    <safety_controller k_position="100.0" k_velocity="40.0" soft_lower_limit="-2.8973" soft_upper_limit="2.8973"/>
    <origin rpy="1.5707963267948966 0 0" xyz="0 -0.316 0"/>
    <parent link="rightpanda_link2"/>
    <child link="rightpanda_link3"/>
    <axis xyz="0 0 1"/>
    <limit effort="2000" lower="-2.8973" upper="2.8973" velocity="2.1750"/>
  </joint>
  <link name="rightpanda_link4">
    <inertial>
      <mass value="2.38"/>
      <origin rpy="0 0 0" xyz="-0.0360446 0.0336853 0.031882"/>
      <inertia ixx="0.00799663881132" ixy="0.00347095570217" ixz="-0.00241222942995" iyy="0.00825390705278" iyz="0.00235774044121" izz="0.0102515004345"/>
    </inertial>
    <visual>
      <!-- <origin xyz="${xyz}" rpy="${rpy}"/> -->
      <geometry>
        <mesh filename="package://master_optimization/model/meshes/visual/link4.dae"/>
      </geometry>
      <material name="">
        <color rgba="1 1 1 1"/>
      </material>
    </visual>
    <collision>
      <!-- <origin xyz="${xyz}" rpy="${rpy}"/> -->
      <geometry>
        <mesh filename="package://master_optimization/model/meshes/collision/link4.stl"/>
      </geometry>
    </collision>
  </link>
  <joint name="rightpanda_joint4" type="revolute">
    <safety_controller k_position="100.0" k_velocity="40.0" soft_lower_limit="-3.0718" soft_upper_limit="0.0698"/>
    <!-- soft_upper_limitr should be -0.0698, but that brakes simulation when initial position for this joint is 0.0 -->
    <origin rpy="1.5707963267948966 0 0" xyz="0.0825 0 0"/>
    <parent link="rightpanda_link3"/>
    <child link="rightpanda_link4"/>
    <axis xyz="0 0 1"/>
    <limit effort="2000" lower="-3.0718" upper="0.0698" velocity="2.1750"/>
    <!-- upper should be -0.0698, but that brakes simulation when initial position for this joint is 0.0 -->
  </joint>
  <link name="rightpanda_link5">
    <inertial>
      <mass value="2.74"/>
      <origin rpy="0 0 0" xyz="0 0.0610427 -0.104176"/>
      <inertia ixx="0.030371374513" ixy="6.50283587108e-07" ixz="-1.05129179916e-05" iyy="0.0288752887402" iyz="-0.00775653445787" izz="0.00444134056164"/>
    </inertial>
    <visual>
      <!-- <origin xyz="${xyz}" rpy="${rpy}"/> -->
      <geometry>
        <mesh filename="package://master_optimization/model/meshes/visual/link5.dae"/>
      </geometry>
      <material name="">
        <color rgba="1 1 1 1"/>
      </material>
    </visual>
    <collision>
      <!-- <origin xyz="${xyz}" rpy="${rpy}"/> -->
      <geometry>
        <mesh filename="package://master_optimization/model/meshes/collision/link5.stl"/>
      </geometry>
    </collision>
  </link>
  <joint name="rightpanda_joint5" type="revolute">
    <safety_controller k_position="100.0" k_velocity="40.0" soft_lower_limit="-2.8973" soft_upper_limit="2.8973"/>
    <origin rpy="-1.5707963267948966 0 0" xyz="-0.0825 0.384 0"/>
    <parent link="rightpanda_link4"/>
    <child link="rightpanda_link5"/>
    <axis xyz="0 0 1"/>
    <limit effort="2000" lower="-2.8973" upper="2.8973" velocity="2.6100"/>
  </joint>
  <link name="rightpanda_link6">
    <inertial>
      <mass value="1.65"/>
      <origin rpy="0 0 0" xyz="0.0510509 0.009108 0.0106343"/>
      <inertia ixx="0.00303336450376" ixy="-0.000437276865508" ixz="0.000629257294877" iyy="0.00404479911567" iyz="0.000130472021025" izz="0.00558234286039"/>
    </inertial>
    <visual>
      <!-- <origin xyz="${xyz}" rpy="${rpy}"/> -->
      <geometry>
        <mesh filename="package://master_optimization/model/meshes/visual/link6.dae"/>
      </geometry>
      <material name="">
        <color rgba="1 1 1 1"/>
      </material>
    </visual>
    <collision>
      <!-- <origin xyz="${xyz}" rpy="${rpy}"/> -->
      <geometry>
        <mesh filename="package://master_optimization/model/meshes/collision/link6.stl"/>
      </geometry>
    </collision>
  </link>
  <joint name="rightpanda_joint6" type="revolute">
    <safety_controller k_position="100.0" k_velocity="40.0" soft_lower_limit="-0.0175" soft_upper_limit="3.7525"/>
    <origin rpy="1.5707963267948966 0 0" xyz="0 0 0"/>
    <parent link="rightpanda_link5"/>
    <child link="rightpanda_link6"/>
    <axis xyz="0 0 1"/>
    <limit effort="12" lower="-0.0175" upper="3.7525" velocity="2.6100"/>
  </joint>
  <link name="rightpanda_link7">
    <inertial>
      <mass value="0.54"/>
      <origin rpy="0 0 0" xyz="0.0109695 0.0107965 0.0650411"/>
      <inertia ixx="0.000888868887021" ixy="-0.00012239074652" ixz="3.98699829666e-05" iyy="0.000888001373233" iyz="-9.33825115206e-05" izz="0.0007176834609"/>
    </inertial>
    <visual>
      <!-- <origin xyz="${xyz}" rpy="${rpy}"/> -->
      <geometry>
        <mesh filename="package://master_optimization/model/meshes/visual/link7.dae"/>
      </geometry>
      <material name="">
        <color rgba="1 1 1 1"/>
      </material>
    </visual>
    <collision>
      <!-- <origin xyz="${xyz}" rpy="${rpy}"/> -->
      <geometry>
        <mesh filename="package://master_optimization/model/meshes/collision/link7.stl"/>
      </geometry>
    </collision>
  </link>
  <joint name="rightpanda_joint7" type="revolute">
    <safety_controller k_position="100.0" k_velocity="40.0" soft_lower_limit="-2.8973" soft_upper_limit="2.8973"/>
    <!-- <safety_controller k_position="100.0" k_velocity="40.0"/> -->
    <origin rpy="1.5707963267948966 0 0" xyz="0.088 0 0"/>
    <parent link="rightpanda_link6"/>
    <child link="rightpanda_link7"/>
    <axis xyz="0 0 1"/>
    <limit effort="12" lower="-2.8973" upper="2.8973" velocity="2.6100"/>
    <!-- <limit effort="12" velocity="2.6100"/> -->
  </joint>
  <link name="rightpanda_link8"/>
  <joint name="rightpanda_joint8" type="fixed">
    <origin rpy="0 0 0" xyz="0 0 0.107"/>
    <parent link="rightpanda_link7"/>
    <child link="rightpanda_link8"/>
    <axis xyz="0 0 0"/>
  </joint>
  <material name="color">
    <color rgba="0 0 1 1"/>
  </material>
  <link name="rightpanda_tmp"/>
  <joint name="rightpanda_joint9" type="fixed">
    <origin rpy="0 0 1.5707" xyz="0 0 0"/>
    <parent link="rightpanda_link8"/>
    <child link="rightpanda_tmp"/>
  </joint>
  <link name="rightpanda_TCP"/>
  <joint name="rightpanda_joint10" type="fixed">
    <origin rpy="0 3.142 0" xyz="0 0 0.07"/>
    <parent link="rightpanda_tmp"/>
    <child link="rightpanda_TCP"/>
  </joint>
  <joint name="worldtoPelvis" type="fixed">
    <origin rpy="0 0 0" xyz="0 0 0"/>
    <parent link="world"/>
    <child link="Pelvis"/>
  </joint>
  <link name="Pelvis">
    <inertial>
      <mass value="0.001"/>
      <!--COM origin wrt pHipOrigin-->
      <origin rpy="0 0 0" xyz="0 0 0.05409"/>
      <inertia ixx="0.052822" ixy="0" ixz="0" iyy="0.019965" iyz="0" izz="0.060476"/>
    </inertial>
    <visual>
      <!--box origin wrt pHipOrigin-->
      <origin rpy="0 0 0" xyz="0 0 0.05409"/>
      <geometry>
        <box size="0.16203 0.29786 0.10818"/>
      </geometry>
      <material name="color"/>
    </visual>
    <collision>
      <!--box origin wrt pHipOrigin-->
      <origin rpy="0 0 0" xyz="0 0 0.05409"/>
      <geometry>
        <box size="0.16203 0.29786 0.10818"/>
      </geometry>
    </collision>
  </link>
  <joint name="jPelvis" type="fixed">
    <origin rpy="0 0 0" xyz="0 0 0.10818"/>
    <parent link="Pelvis"/>
    <child link="L5"/>
  </joint>
  <link name="L5">
    <inertial>
      <mass value="0.001"/>
      <!--COM origin wrt jL5S1-->
      <origin rpy="0 0 0" xyz="0 0 0.044243"/>
      <inertia ixx="0.029829" ixy="0" ixz="0" iyy="0.022858" iyz="0" izz="0.042185"/>
    </inertial>
    <visual>
      <!--box origin origin wrt jL5S1-->
      <origin rpy="0 0 0" xyz="0 0 0.044243"/>
      <geometry>
        <box size="0.16203 0.19144 0.088486"/>
      </geometry>
      <material name="color"/>
    </visual>
    <collision>
      <!--box origin origin wrt jL5S1-->
      <origin rpy="0 0 0" xyz="0 0 0.044243"/>
      <geometry>
        <box size="0.16203 0.19144 0.088486"/>
      </geometry>
    </collision>
  </link>
  <joint name="jL5L3" type="fixed">
    <origin rpy="0 0 0" xyz="0 0 0.088486"/>
    <parent link="L5"/>
    <child link="L3"/>
  </joint>
  <link name="L3">
    <inertial>
      <mass value="0.001"/>
      <!--COM origin wrt jL4L3-->
      <origin rpy="0 0 0" xyz="0 0 0.039957"/>
      <inertia ixx="0.028861" ixy="0" ixz="0" iyy="0.02189" iyz="0" izz="0.042185"/>
    </inertial>
    <visual>
      <!--box origin origin wrt jL4L3-->
      <origin rpy="0 0 0" xyz="0 0 0.039957"/>
      <geometry>
        <box size="0.16203 0.19144 0.079914"/>
      </geometry>
      <material name="color"/>
    </visual>
    <collision>
      <!--box origin origin wrt jL4L3-->
      <origin rpy="0 0 0" xyz="0 0 0.039957"/>
      <geometry>
        <box size="0.16203 0.19144 0.079914"/>
      </geometry>
    </collision>
  </link>
  <joint name="jL1T12_rotx" type="fixed">
    <origin rpy="0 0 0" xyz="0 0 0.079914"/>
    <parent link="L3"/>
    <child link="T12"/>
  </joint>
  <link name="T12">
    <inertial>
      <mass value="0.001"/>
      <!--COM origin wrt jL1T12-->
      <origin rpy="0 0 0" xyz="0 0 0.039957"/>
      <inertia ixx="0.028861" ixy="0" ixz="0" iyy="0.02189" iyz="0" izz="0.042185"/>
    </inertial>
    <visual>
      <!--box origin origin wrt jL1T12-->
      <origin rpy="0 0 0" xyz="0 0 0.039957"/>
      <geometry>
        <box size="0.16203 0.19144 0.079914"/>
      </geometry>
      <material name="color"/>
    </visual>
    <collision>
      <!--box origin origin wrt jL1T12-->
      <origin rpy="0 0 0" xyz="0 0 0.039957"/>
      <geometry>
        <box size="0.16203 0.19144 0.079914"/>
      </geometry>
    </collision>
  </link>
  <joint name="jT9T8_rotx" type="fixed">
    <origin rpy="0 0 0" xyz="0 0 0.079914"/>
    <parent link="T12"/>
    <child link="T8"/>
  </joint>
  <link name="T8">
    <inertial>
      <mass value="0.001"/>
      <!--COM origin wrt jT9T8-->
      <origin rpy="0 0 0" xyz="0 0 0.057446"/>
      <inertia ixx="0.0044311" ixy="0" ixz="0" iyy="0.0085523" iyz="0" izz="0.0060402"/>
    </inertial>
    <visual>
      <!--box origin wrt jT9T8-->
      <origin rpy="0 0 0" xyz="0 0 0.057446"/>
      <geometry>
        <box size="0.13899 0.0604 0.11489"/>
      </geometry>
      <material name="color"/>
    </visual>
    <collision>
      <!--box origin wrt jT9T8-->
      <origin rpy="0 0 0" xyz="0 0 0.057446"/>
      <geometry>
        <box size="0.13899 0.0604 0.11489"/>
      </geometry>
    </collision>
  </link>
  <joint name="jT8Neck" type="fixed">
    <origin rpy="0 0 0" xyz="0 0 0.11489"/>
    <parent link="T8"/>
    <child link="Neck"/>
  </joint>
  <link name="Neck">
    <inertial>
      <mass value="0.001"/>
      <!--COM origin wrt jT1C7-->
      <origin rpy="0 0 0" xyz="0 0 0.045875"/>
      <inertia ixx="0.00087909" ixy="0" ixz="0" iyy="0.00087909" iyz="0" izz="0.00042982"/>
    </inertial>
    <visual>
      <!--box origin wrt jT1C7-->
      <origin rpy="0 0 0" xyz="0 0 0.045875"/>
      <geometry>
        <cylinder length="0.09175" radius="0.015066"/>
      </geometry>
      <material name="color"/>
    </visual>
    <collision>
      <!--box origin wrt jT1C7-->
      <origin rpy="0 0 0" xyz="0 0 0.045875"/>
      <geometry>
        <cylinder length="0.09175" radius="0.015066"/>
      </geometry>
    </collision>
  </link>
  <joint name="jNeckHead" type="fixed">
    <origin rpy="0 0 0" xyz="0.001481 0 0.09175"/>
    <parent link="Neck"/>
    <child link="Head"/>
    <dynamics damping="0.1" friction="0.0"/>
    <limit effort="30" lower="-0.610865" upper="0.610865" velocity="1.0"/>
    <axis xyz="1 0 0"/>
  </joint>
  <link name="Head">
    <inertial>
      <mass value="2.8404"/>
      <!--COM origin wrt jC1Head-->
      <origin rpy="0 0 0" xyz="0 0 0.092703"/>
      <inertia ixx="0.0097641" ixy="0" ixz="0" iyy="0.0097641" iyz="0" izz="0.0097641"/>
    </inertial>
    <visual>
      <!--boc origin wrt jC1Head-->
      <origin rpy="0 0 0" xyz="0 0 0.092703"/>
      <geometry>
        <sphere radius="0.092703"/>
      </geometry>
      <material name="color"/>
    </visual>
    <collision>
      <!--box origin wrt jC1Head-->
      <origin rpy="0 0 0" xyz="0 0 0.092703"/>
      <geometry>
        <sphere radius="0.092703"/>
      </geometry>
    </collision>
  </link>
  <!-- RIGHT ARM -->
  <joint name="jT8RightShoulder" type="fixed">
    <origin rpy="0 0 0" xyz="0 -0.0302 0.064859"/>
    <parent link="T8"/>
    <child link="RightShoulder"/>
  </joint>
  <link name="RightShoulder">
    <inertial>
      <mass value="0.001"/>
      <!--COM origin wrt jRightC7Shoulder-->
      <origin rpy="0 0 0" xyz="0 -0.081595  0"/>
      <inertia ixx="0.0059341" ixy="0" ixz="0" iyy="0.0010123" iyz="0" izz="0.0059341"/>
    </inertial>
    <visual>
      <!--box origin wrt jRightC7Shoulder. RPY rotated of pi/2.-->
      <origin rpy="1.5708 0 0" xyz="0 -0.081595 0"/>
      <geometry>
        <cylinder length="0.16319" radius="0.02877"/>
      </geometry>
      <material name="color"/>
    </visual>
    <collision>
      <!--box origin wrt jRightC7Shoulder. RPY rotated of pi/2.-->
      <origin rpy="1.5708 0 0" xyz="0 -0.081595 0"/>
      <geometry>
        <cylinder length="0.16319" radius="0.02877"/>
      </geometry>
    </collision>
  </link>
  <joint name="jRight_1" type="revolute">
    <origin rpy="1.5708 0 0" xyz="0 -0.16319 0"/>
    <parent link="RightShoulder"/>
    <child link="Right1"/>
    <dynamics damping="0.1" friction="0.0"/>
    <limit effort="30" lower="-0.5236" upper="3.14159" velocity="1.0"/>
    <axis xyz="0 0 1"/>
  </joint>
  <link name="Right1">
    <inertial>
      <mass value="0.0001"/>
      <origin rpy="0 0 0" xyz="0 0 0"/>
      <inertia ixx="0.0001" ixy="0" ixz="0" iyy="0.0001" iyz="0" izz="0.0001"/>
    </inertial>
  </link>
  <joint name="jRight_2" type="revolute">
    <origin rpy="0 0 0" xyz="0 0 0"/>
    <parent link="Right1"/>
    <child link="Right2"/>
    <dynamics damping="0.1" friction="0.0"/>
    <limit effort="30" lower="-0.8727" upper="1.5708" velocity="1.0"/>
    <axis xyz="-1 0 0"/>
  </joint>
  <link name="Right2">
    <inertial>
      <mass value="0.0001"/>
      <origin rpy="0 0 0" xyz="0 0 0"/>
      <inertia ixx="0.0001" ixy="0" ixz="0" iyy="0.0001" iyz="0" izz="0.0001"/>
    </inertial>
  </link>
  <joint name="jRight_3" type="revolute">
    <origin rpy="0 0 0" xyz="0 0 0"/>
    <parent link="Right2"/>
    <child link="Right3"/>
    <dynamics damping="0.1" friction="0.0"/>
    <limit effort="30" lower="-1.3962" upper="1.3962" velocity="1.0"/>
    <axis xyz="0 -1 0"/>
  </joint>
  <link name="Right3">
    <inertial>
      <mass value="0.0001"/>
      <origin rpy="0 0 0" xyz="0 0 0"/>
      <inertia ixx="0.0001" ixy="0" ixz="0" iyy="0.0001" iyz="0" izz="0.0001"/>
    </inertial>
    <visual>
      <!--box origin wrt jRightShoulder. RPY rotated of pi/2.-->
      <origin rpy="1.5708 0 0" xyz="0 -0.15754 0"/>
      <geometry>
        <cylinder length="0.31509" radius="0.034205"/>
      </geometry>
      <material name="color"/>
    </visual>
    <collision>
      <!--box origin wrt jRightShoulder. RPY rotated of pi/2.-->
      <origin rpy="1.5708 0 0" xyz="0 -0.15754 0"/>
      <geometry>
        <cylinder length="0.31509" radius="0.034205"/>
      </geometry>
    </collision>
  </link>
  <joint name="jRight_4" type="revolute">
    <origin rpy="0 0 0" xyz="0 -0.31509 0"/>
    <parent link="Right3"/>
    <child link="Right4"/>
    <dynamics damping="0.1" friction="0.0"/>
    <limit effort="30" lower="0" upper="2.7925" velocity="1.0"/>
    <axis xyz="0 0 1"/>
  </joint>
  <link name="Right4">
    <inertial>
      <mass value="0.0001"/>
      <origin rpy="0 0 0" xyz="0 0 0"/>
      <inertia ixx="0.0001" ixy="0" ixz="0" iyy="0.0001" iyz="0" izz="0.0001"/>
    </inertial>
  </link>
  <joint name="jRight_5" type="revolute">
    <origin rpy="0 0 0" xyz="0 0 0"/>
    <parent link="Right4"/>
    <child link="Right5"/>
    <dynamics damping="0.1" friction="0.0"/>
    <limit effort="30" lower="-1.5708" upper="1.4835" velocity="1.0"/>
    <axis xyz="0 -1 0"/>
  </joint>
  <link name="Right5">
    <inertial>
      <mass value="0.0001"/>
      <origin rpy="0 0 0" xyz="0 0 0"/>
      <inertia ixx="0.0001" ixy="0" ixz="0" iyy="0.0001" iyz="0" izz="0.0001"/>
    </inertial>
    <visual>
      <!--box origin wrt jRightShoulder. RPY rotated of pi/2.-->
      <origin rpy="1.5708 0 0" xyz="0 -0.1292 0"/>
      <geometry>
        <cylinder length="0.2584" radius="0.022803"/>
      </geometry>
      <material name="color"/>
    </visual>
    <collision>
      <!--box origin wrt jRightShoulder. RPY rotated of pi/2.-->
      <origin rpy="1.5708 0 0" xyz="0 -0.1292 0"/>
      <geometry>
        <cylinder length="0.2584" radius="0.022803"/>
      </geometry>
    </collision>
  </link>
  <joint name="jRight_6" type="revolute">
    <origin rpy="0 0 0" xyz="0 -0.2584 0"/>
    <parent link="Right5"/>
    <child link="Right6"/>
    <dynamics damping="0.1" friction="0.0"/>
    <limit effort="30" lower="-1.4835" upper="1.4835" velocity="1.0"/>
    <axis xyz="0 0 1"/>
  </joint>
  <link name="Right6">
    <inertial>
      <mass value="0.0001"/>
      <origin rpy="0 0 0" xyz="0 0 0"/>
      <inertia ixx="0.0001" ixy="0" ixz="0" iyy="0.0001" iyz="0" izz="0.0001"/>
    </inertial>
  </link>
  <joint name="jRight_7" type="revolute">
    <origin rpy="0 0 0" xyz="0 0 0"/>
    <parent link="Right6"/>
    <child link="Right7"/>
    <dynamics damping="0.1" friction="0.0"/>
    <limit effort="30" lower="-0.7854" upper="0.2618" velocity="1.0"/>
    <axis xyz="-1 0 0"/>
  </joint>
  <link name="Right7">
    <inertial>
      <mass value="0.001"/>
      <!--COM origin wrt jRightWrist-->
      <origin rpy="0 0 0" xyz="0 -0.075 0"/>
      <inertia ixx="0.001" ixy="0" ixz="0" iyy="0.001" iyz="0" izz="0.001"/>
    </inertial>
    <visual>
      <!--box origin wrt jRightWrist-->
      <origin rpy="0 0 0" xyz="0 -0.075 0"/>
      <geometry>
        <!-- <box size="0.12916 0.19374 0.045607"/> -->
        <box size="0.045607 0.15 0.09"/>
      </geometry>
      <material name="color"/>
    </visual>
    <collision>
      <!--box origin wrt jRightWrist-->
      <origin rpy="0 0 0" xyz="0 -0.075 0"/>
      <geometry>
        <!-- <box size="0.12916 0.19374 0.045607"/> -->
        <box size="0.045607 0.15 0.09"/>
      </geometry>
    </collision>
  </link>
  <joint name="jRight_8" type="fixed">
    <origin rpy="0 0 0" xyz="0 -0.05 0"/>
    <parent link="Right7"/>
    <child link="RightTCP"/>
  </joint>
  <link name="RightTCP"/>
  <!-- LEFT ARM -->
  <joint name="jT8LeftShoulder" type="fixed">
    <origin rpy="0 0 0" xyz="0 0.0302 0.064859"/>
    <parent link="T8"/>
    <child link="LeftShoulder"/>
  </joint>
  <link name="LeftShoulder">
    <inertial>
      <mass value="0.001"/>
      <!--COM origin wrt jRightC7Shoulder-->
      <origin rpy="0 0 0" xyz="0 0.081595  0"/>
      <inertia ixx="0.0059341" ixy="0" ixz="0" iyy="0.0010123" iyz="0" izz="0.0059341"/>
    </inertial>
    <visual>
      <!--box origin wrt jRightC7Shoulder. RPY rotated of pi/2.-->
      <origin rpy="1.5708 0 0" xyz="0 0.081595 0"/>
      <geometry>
        <cylinder length="0.16319" radius="0.02877"/>
      </geometry>
      <material name="color"/>
    </visual>
    <collision>
      <!--box origin wrt jRightC7Shoulder. RPY rotated of pi/2.-->
      <origin rpy="1.5708 0 0" xyz="0 0.081595 0"/>
      <geometry>
        <cylinder length="0.16319" radius="0.02877"/>
      </geometry>
    </collision>
  </link>
  <joint name="jLeft_1" type="revolute">
    <origin rpy="1.5708 0 0" xyz="0 0.16319 0"/>
    <parent link="LeftShoulder"/>
    <child link="Left1"/>
    <dynamics damping="0.1" friction="0.0"/>
    <limit effort="30" lower="-0.5236" upper="3.14159" velocity="1.0"/>
    <axis xyz="0 0 1"/>
  </joint>
  <link name="Left1">
    <inertial>
      <mass value="0.0001"/>
      <origin rpy="0 0 0" xyz="0 0 0"/>
      <inertia ixx="0.0001" ixy="0" ixz="0" iyy="0.0001" iyz="0" izz="0.0001"/>
    </inertial>
  </link>
  <joint name="jLeft_2" type="revolute">
    <origin rpy="0 0 0" xyz="0 0 0"/>
    <parent link="Left1"/>
    <child link="Left2"/>
    <dynamics damping="0.1" friction="0.0"/>
    <limit effort="30" lower="-1.5708" upper="0.8727" velocity="1.0"/>
    <axis xyz="-1 0 0"/>
  </joint>
  <link name="Left2">
    <inertial>
      <mass value="0.0001"/>
      <origin rpy="0 0 0" xyz="0 0 0"/>
      <inertia ixx="0.0001" ixy="0" ixz="0" iyy="0.0001" iyz="0" izz="0.0001"/>
    </inertial>
  </link>
  <joint name="jLeft_3" type="revolute">
    <origin rpy="0 0 0" xyz="0 0 0"/>
    <parent link="Left2"/>
    <child link="Left3"/>
    <dynamics damping="0.1" friction="0.0"/>
    <limit effort="30" lower="-1.3962" upper="1.3962" velocity="1.0"/>
    <axis xyz="0 -1 0"/>
  </joint>
  <link name="Left3">
    <inertial>
      <mass value="0.0001"/>
      <origin rpy="0 0 0" xyz="0 0 0"/>
      <inertia ixx="0.0001" ixy="0" ixz="0" iyy="0.0001" iyz="0" izz="0.0001"/>
    </inertial>
    <visual>
      <!--box origin wrt jRightShoulder. RPY rotated of pi/2.-->
      <origin rpy="1.5708 0 0" xyz="0 -0.15754 0"/>
      <geometry>
        <cylinder length="0.31509" radius="0.034205"/>
      </geometry>
      <material name="color"/>
    </visual>
    <collision>
      <!--box origin wrt jRightShoulder. RPY rotated of pi/2.-->
      <origin rpy="1.5708 0 0" xyz="0 -0.15754 0"/>
      <geometry>
        <cylinder length="0.31509" radius="0.034205"/>
      </geometry>
    </collision>
  </link>
  <joint name="jLeft_4" type="revolute">
    <origin rpy="0 0 0" xyz="0 -0.31509 0"/>
    <parent link="Left3"/>
    <child link="Left4"/>
    <dynamics damping="0.1" friction="0.0"/>
    <limit effort="30" lower="0" upper="2.7925" velocity="1.0"/>
    <axis xyz="0 0 1"/>
  </joint>
  <link name="Left4">
    <inertial>
      <mass value="0.0001"/>
      <origin rpy="0 0 0" xyz="0 0 0"/>
      <inertia ixx="0.0001" ixy="0" ixz="0" iyy="0.0001" iyz="0" izz="0.0001"/>
    </inertial>
  </link>
  <joint name="jLeft_5" type="revolute">
    <origin rpy="0 0 0" xyz="0 0 0"/>
    <parent link="Left4"/>
    <child link="Left5"/>
    <dynamics damping="0.1" friction="0.0"/>
    <limit effort="30" lower="-1.4835" upper="1.5708" velocity="1.0"/>
    <axis xyz="0 -1 0"/>
  </joint>
  <link name="Left5">
    <inertial>
      <mass value="0.0001"/>
      <origin rpy="0 0 0" xyz="0 0 0"/>
      <inertia ixx="0.0001" ixy="0" ixz="0" iyy="0.0001" iyz="0" izz="0.0001"/>
    </inertial>
    <visual>
      <!--box origin wrt jRightShoulder. RPY rotated of pi/2.-->
      <origin rpy="1.5708 0 0" xyz="0 -0.1292 0"/>
      <geometry>
        <cylinder length="0.2584" radius="0.022803"/>
      </geometry>
      <material name="color"/>
    </visual>
    <collision>
      <!--box origin wrt jRightShoulder. RPY rotated of pi/2.-->
      <origin rpy="1.5708 0 0" xyz="0 -0.1292 0"/>
      <geometry>
        <cylinder length="0.2584" radius="0.022803"/>
      </geometry>
    </collision>
  </link>
  <joint name="jLeft_6" type="revolute">
    <origin rpy="0 0 0" xyz="0 -0.2584 0"/>
    <parent link="Left5"/>
    <child link="Left6"/>
    <dynamics damping="0.1" friction="0.0"/>
    <limit effort="30" lower="-1.4835" upper="1.4835" velocity="1.0"/>
    <axis xyz="0 0 1"/>
  </joint>
  <link name="Left6">
    <inertial>
      <mass value="0.0001"/>
      <origin rpy="0 0 0" xyz="0 0 0"/>
      <inertia ixx="0.0001" ixy="0" ixz="0" iyy="0.0001" iyz="0" izz="0.0001"/>
    </inertial>
  </link>
  <joint name="jLeft_7" type="revolute">
    <origin rpy="0 0 0" xyz="0 0 0"/>
    <parent link="Left6"/>
    <child link="Left7"/>
    <dynamics damping="0.1" friction="0.0"/>
    <limit effort="30" lower="-0.2618" upper="0.7854" velocity="1.0"/>
    <axis xyz="-1 0 0"/>
  </joint>
  <link name="Left7">
    <inertial>
      <mass value="0.001"/>
      <!--COM origin wrt jRightWrist-->
      <origin rpy="0 0 0" xyz="0 -0.096871 0"/>
      <inertia ixx="0.001" ixy="0" ixz="0" iyy="0.001" iyz="0" izz="0.001"/>
    </inertial>
    <visual>
      <!--box origin wrt jRightWrist-->
      <origin rpy="0 0 0" xyz="0 -0.075 0"/>
      <geometry>
        <!-- <box size="0.12916 0.19374 0.045607"/> -->
        <box size="0.045607 0.15 0.09"/>
      </geometry>
      <material name="color"/>
    </visual>
    <collision>
      <!--box origin wrt jRightWrist-->
      <origin rpy="0 0 0" xyz="0 -0.075 0"/>
      <geometry>
        <!-- <box size="0.12916 0.19374 0.045607"/> -->
        <box size="0.045607 0.15 0.09"/>
      </geometry>
    </collision>
  </link>
  <joint name="jLeft_8" type="fixed">
    <origin rpy="0 0 0" xyz="0 -0.05 0"/>
    <parent link="Left7"/>
    <child link="LeftTCP"/>
  </joint>
  <link name="LeftTCP"/>
</robot>
